Workbook
Name db5_expression: #REF!

Sheet Summary
A1: Network structure: | F1: Trial | G1: B constant | H1: No constant | I1: P constant | J1: PB constant | K1: Sum | N1: Trial | O1: No constant | P1: PB constant | Q1: Median | R1: Median
A2: cols regulators/rows targets | B2: gene1 | C2: gene2 | D2: gene3 | F2: 19.01 | G2: ='19.01'!G13 -> 3.4219635e-08 | H2: ='19.01'!L13 -> 1.9470857 | I2: ='19.01'!Q13 -> 3.1233063e-07 | J2: ='19.01'!V13 -> 2.0881437e-12 | K2: =SUM(G2:J2) -> 1.947086 | N2: 19.2 | O2: 0.051527153 | P2: 2.3332019e-07 | Q2: =$O$26 -> 0.87566406 | R2: =$P$26 -> 2.6519441e-10
A3: gene1 | B3: 1 | C3: 0 | D3: 0 | F3: 19.02 | G3: ='19.02'!G13 -> 0.24939177 | H3: ='19.02'!L13 -> 0.82711497 | I3: ='19.02'!Q13 -> 9.0735957e-08 | J3: ='19.02'!V13 -> 2.5180776e-10 | K3: =SUM(G3:J3) -> 1.0765068 | N3: 19.14 | O3: 0.15400575 | P3: 1.4199345e-06 | Q3: =$O$26 -> 0.87566406 | R3: =$P$26 -> 2.6519441e-10
A4: gene2 | B4: 0 | C4: 1 | D4: 0 | F4: 19.03 | G4: ='19.03'!G13 -> 3.6923107e-08 | H4: ='19.03'!L13 -> 2.5811204 | I4: ='19.03'!Q13 -> 2.2335303e-07 | J4: ='19.03'!V13 -> 2.5539784e-12 | K4: =SUM(G4:J4) -> 2.5811207 | N4: 19.04 | O4: 0.17345373 | P4: 1.0312979e-10 | Q4: =$O$26 -> 0.87566406 | R4: =$P$26 -> 2.6519441e-10
A5: gene3 | B5: 1 | C5: 1 | D5: 0 | F5: 19.04 | G5: ='19.04'!G13 -> 35.791326 | H5: ='19.04'!L13 -> 0.17345373 | I5: ='19.04'!Q13 -> 1.2757251e-10 | J5: ='19.04'!V13 -> 1.0312979e-10 | K5: =SUM(G5:J5) -> 35.964779 | N5: 19.22 | O5: 0.18769072 | P5: 1.4199758e-06 | Q5: =$O$26 -> 0.87566406 | R5: =$P$26 -> 2.6519441e-10
F6: 19.05 | G6: ='19.05'!G13 -> 3.4219635e-08 | H6: ='19.05'!L13 -> 1.9470857 | I6: ='19.05'!Q13 -> 3.1233063e-07 | J6: ='19.05'!V13 -> 2.0881437e-12 | K6: =SUM(G6:J6) -> 1.947086 | N6: 19.19 | O6: 0.23182368 | P6: 2.047701e-10 | Q6: =$O$26 -> 0.87566406 | R6: =$P$26 -> 2.6519441e-10
F7: 19.06 | G7: ='19.06'!G13 -> 0.009970327 | H7: ='19.06'!L13 -> 0.91994801 | I7: ='19.06'!Q13 -> 1.5787184e-07 | J7: ='19.06'!V13 -> 4.7249995e-10 | K7: =SUM(G7:J7) -> 0.92991849 | N7: 19.1 | O7: 0.29665338 | P7: 2.0477022e-10 | Q7: =$O$26 -> 0.87566406 | R7: =$P$26 -> 2.6519441e-10
F8: 19.07 | G8: ='19.07'!G13 -> 0.00053688354 | H8: ='19.07'!L13 -> 3.0329404 | I8: ='19.07'!Q13 -> 6.8161965e-09 | J8: ='19.07'!V13 -> 2.6319783e-08 | K8: =SUM(G8:J8) -> 3.0334773 | N8: 19.21 | O8: 0.33920257 | P8: 1.0312978e-10 | Q8: =$O$26 -> 0.87566406 | R8: =$P$26 -> 2.6519441e-10
F9: 19.08 | G9: ='19.08'!G13 -> 36.064659 | H9: ='19.08'!L13 -> 3.9638656 | I9: ='19.08'!Q13 -> 1.0115312e-09 | J9: ='19.08'!V13 -> 6.4617947e-10 | K9: =SUM(G9:J9) -> 40.028525 | N9: 19.15 | O9: 0.3426086 | P9: 4.7249992e-10 | Q9: =$O$26 -> 0.87566406 | R9: =$P$26 -> 2.6519441e-10
F10: 19.09 | G10: ='19.09'!G13 -> 3.4219731e-08 | H10: ='19.09'!L13 -> 1.694395 | I10: ='19.09'!Q13 -> 3.1233025e-07 | J10: ='19.09'!V13 -> 2.0881441e-12 | K10: =SUM(G10:J10) -> 1.6943953 | N10: 19.16 | O10: 0.34870635 | P10: 2.3331989e-07 | Q10: =$O$26 -> 0.87566406 | R10: =$P$26 -> 2.6519441e-10
F11: 19.1 | G11: ='19.10'!G13 -> 23.34348 | H11: ='19.10'!L13 -> 0.29665338 | I11: ='19.10'!Q13 -> 1.6815659e-10 | J11: ='19.10'!V13 -> 2.0477022e-10 | K11: =SUM(G11:J11) -> 23.640133 | N11: 19.24 | O11: 0.6206257 | P11: 6.4617952e-10 | Q11: =$O$26 -> 0.87566406 | R11: =$P$26 -> 2.6519441e-10
F12: 19.11 | G12: ='19.11'!G13 -> 3.6923016e-08 | H12: ='19.11'!L13 -> 2.7223037 | I12: ='19.11'!Q13 -> 2.2335223e-07 | J12: ='19.11'!V13 -> 2.5539762e-12 | K12: =SUM(G12:J12) -> 2.722304 | N12: 19.02 | O12: 0.82711497 | P12: 2.5180776e-10 | Q12: =$O$26 -> 0.87566406 | R12: =$P$26 -> 2.6519441e-10
F13: 19.12 | G13: ='19.12'!G13 -> 26.473942 | H13: ='19.12'!L13 -> 1.0344398 | I13: ='19.12'!Q13 -> 3.479984e-10 | J13: ='19.12'!V13 -> 2.6519441e-10 | K13: =SUM(G13:J13) -> 27.508382 | N13: 19.23 | O13: 0.83138011 | P13: 2.5180764e-10 | Q13: =$O$26 -> 0.87566406 | R13: =$P$26 -> 2.6519441e-10
F14: 19.13 | G14: ='19.13'!G13 -> 11.804979 | H14: ='19.13'!L13 -> 1.0394427 | I14: ='19.13'!Q13 -> 3.4799832e-10 | J14: ='19.13'!V13 -> 2.6519442e-10 | K14: =SUM(G14:J14) -> 12.844422 | N14: 19.06 | O14: 0.91994801 | P14: 4.7249995e-10 | Q14: =$O$26 -> 0.87566406 | R14: =$P$26 -> 2.6519441e-10
F15: 19.14 | G15: ='19.14'!G13 -> 0.090824318 | H15: ='19.14'!L13 -> 0.15400575 | I15: ='19.14'!Q13 -> 4.7034121e-11 | J15: ='19.14'!V13 -> 1.4199345e-06 | K15: =SUM(G15:J15) -> 0.24483149 | N15: 19.12 | O15: 1.0344398 | P15: 2.6519441e-10 | Q15: =$O$26 -> 0.87566406 | R15: =$P$26 -> 2.6519441e-10
F16: 19.15 | G16: ='19.15'!G13 -> 0.00017618408 | H16: ='19.15'!L13 -> 0.3426086 | I16: ='19.15'!Q13 -> 1.5787218e-07 | J16: ='19.15'!V13 -> 4.7249992e-10 | K16: =SUM(G16:J16) -> 0.34278495 | N16: 19.13 | O16: 1.0394427 | P16: 2.6519442e-10 | Q16: =$O$26 -> 0.87566406 | R16: =$P$26 -> 2.6519441e-10
F17: 19.16 | G17: ='19.16'!G13 -> 0.080934338 | H17: ='19.16'!L13 -> 0.34870635 | I17: ='19.16'!Q13 -> 2.2640224e-08 | J17: ='19.16'!V13 -> 2.3331989e-07 | K17: =SUM(G17:J17) -> 0.42964094 | N17: 19.09 | O17: 1.694395 | P17: 2.0881441e-12 | Q17: =$O$26 -> 0.87566406 | R17: =$P$26 -> 2.6519441e-10 | AB17: -2 | AC17: -2 | AD17: -1 | AE17: -1 | AF17: -2 | AG17: 2 | AH17: -2 | AI17: 2 | AJ17: -2 | AK17: 2 | AL17: -2 | AM17: -1 | AN17: 1 | AO17: 1 | AP17: -2 | AQ17: -1 | AR17: 2 | AS17: -1 | AT17: 1 | AU17: 1 | AV17: 1 | AW17: -2 | AX17: 1 | AY17: 2
F18: 19.17 | G18: ='19.17'!G13 -> 34.594685 | H18: ='19.17'!L13 -> 4.4820955 | I18: ='19.17'!Q13 -> 4.4448084e-08 | J18: ='19.17'!V13 -> 4.0626556e-08 | K18: =SUM(G18:J18) -> 39.076781 | N18: 19.01 | O18: 1.9470857 | P18: 2.0881437e-12 | Q18: =$O$26 -> 0.87566406 | R18: =$P$26 -> 2.6519441e-10 | AB18: -1 | AC18: 2 | AD18: 1 | AE18: 2 | AF18: 1 | AG18: -1 | AH18: 1 | AI18: -2 | AJ18: -1 | AK18: 1 | AL18: -1 | AM18: 2 | AN18: -2 | AO18: -1 | AP18: 2 | AQ18: -2 | AR18: 1 | AS18: -2 | AT18: 2 | AU18: 2 | AV18: -1 | AW18: -1 | AX18: -2 | AY18: -1
F19: 19.18 | G19: ='19.18'!G13 -> 0.00053687312 | H19: ='19.18'!L13 -> 4.3882643 | I19: ='19.18'!Q13 -> 6.8161982e-09 | J19: ='19.18'!V13 -> 2.63198e-08 | K19: =SUM(G19:J19) -> 4.3888012 | N19: 19.05 | O19: 1.9470857 | P19: 2.0881437e-12 | Q19: =$O$26 -> 0.87566406 | R19: =$P$26 -> 2.6519441e-10 | AB19: 1 | AC19: -1 | AD19: -2 | AE19: -2 | AF19: -1 | AG19: -2 | AH19: 2 | AI19: -1 | AJ19: 1 | AK19: -2 | AL19: 2 | AM19: 1 | AN19: -1 | AO19: -2 | AP19: 1 | AQ19: 2 | AR19: -1 | AS19: 1 | AT19: -1 | AU19: -2 | AV19: 2 | AW19: 2 | AX19: 2 | AY19: 1
F20: 19.19 | G20: ='19.19'!G13 -> 23.348067 | H20: ='19.19'!L13 -> 0.23182368 | I20: ='19.19'!Q13 -> 1.6815656e-10 | J20: ='19.19'!V13 -> 2.047701e-10 | K20: =SUM(G20:J20) -> 23.579891 | N20: 19.03 | O20: 2.5811204 | P20: 2.5539784e-12 | Q20: =$O$26 -> 0.87566406 | R20: =$P$26 -> 2.6519441e-10 | AB20: 2 | AC20: 1 | AD20: 2 | AE20: 1 | AF20: 2 | AG20: 1 | AH20: -1 | AI20: 1 | AJ20: 2 | AK20: -1 | AL20: 1 | AM20: -2 | AN20: 2 | AO20: 2 | AP20: -1 | AQ20: 1 | AR20: -2 | AS20: 2 | AT20: -2 | AU20: -1 | AV20: -2 | AW20: 1 | AX20: -1 | AY20: -2
F21: 19.2 | G21: ='19.20'!G13 -> 0.080942898 | H21: ='19.20'!L13 -> 0.051527153 | I21: ='19.20'!Q13 -> 2.2640225e-08 | J21: ='19.20'!V13 -> 2.3332019e-07 | K21: =SUM(G21:J21) -> 0.13247031 | N21: 19.11 | O21: 2.7223037 | P21: 2.5539762e-12 | Q21: =$O$26 -> 0.87566406 | R21: =$P$26 -> 2.6519441e-10
F22: 19.21 | G22: ='19.21'!G13 -> 19.803615 | H22: ='19.21'!L13 -> 0.33920257 | I22: ='19.21'!Q13 -> 1.2757257e-10 | J22: ='19.21'!V13 -> 1.0312978e-10 | K22: =SUM(G22:J22) -> 20.142817 | N22: 19.07 | O22: 3.0329404 | P22: 2.6319783e-08 | Q22: =$O$26 -> 0.87566406 | R22: =$P$26 -> 2.6519441e-10
F23: 19.22 | G23: ='19.22'!G13 -> 0.090860359 | H23: ='19.22'!L13 -> 0.18769072 | I23: ='19.22'!Q13 -> 4.7034217e-11 | J23: ='19.22'!V13 -> 1.4199758e-06 | K23: =SUM(G23:J23) -> 0.27855249 | N23: 19.08 | O23: 3.9638656 | P23: 6.4617947e-10 | Q23: =$O$26 -> 0.87566406 | R23: =$P$26 -> 2.6519441e-10
F24: 19.23 | G24: ='19.23'!G13 -> 0.25281201 | H24: ='19.23'!L13 -> 0.83138011 | I24: ='19.23'!Q13 -> 9.0734497e-08 | J24: ='19.23'!V13 -> 2.5180764e-10 | K24: =SUM(G24:J24) -> 1.0841922 | N24: 19.18 | O24: 4.3882643 | P24: 2.63198e-08 | Q24: =$O$26 -> 0.87566406 | R24: =$P$26 -> 2.6519441e-10
F25: 19.24 | G25: ='19.24'!G13 -> 33.766681 | H25: ='19.24'!L13 -> 0.6206257 | I25: ='19.24'!Q13 -> 1.0115307e-09 | J25: ='19.24'!V13 -> 6.4617952e-10 | K25: =SUM(G25:J25) -> 34.387307 | N25: 19.17 | O25: 4.4820955 | P25: 4.0626556e-08 | Q25: =$O$26 -> 0.87566406 | R25: =$P$26 -> 2.6519441e-10
G26: =SUM(G2:G25) -> 245.84842 | H26: =SUM(H2:H25) -> 34.15778 | I26: =SUM(I2:I25) -> 1.9876768e-06 | J26: =SUM(J2:J25) -> 3.4037151e-06 | O26: =MEDIAN(O2:O25) -> 0.87566406 | P26: =MEDIAN(P2:P25) -> 2.6519441e-10
A31: Weights: | AB31: -2 | AC31: -1 | AD31: -1 | AE31: -2 | AF31: 1 | AG31: 1 | AH31: 2 | AI31: 2 | AJ31: -1 | AK31: -2 | AL31: 1 | AM31: 2 | AN31: -2 | AO31: -1 | AP31: 1 | AQ31: 2 | AR31: -1 | AS31: 2 | AT31: -2 | AU31: -2 | AV31: 2 | AW31: 1 | AX31: -1 | AY31: 1
A32: Perm | B32: 19.01 | C32: 19.02 | D32: 19.03 | E32: 19.04 | F32: 19.05 | G32: 19.06 | H32: 19.07 | I32: 19.08 | J32: 19.09 | K32: 19.1 | L32: 19.11 | M32: 19.12 | N32: 19.13 | O32: 19.14 | P32: 19.15 | Q32: 19.16 | R32: 19.17 | S32: 19.18 | T32: 19.19 | U32: 19.2 | V32: 19.21 | W32: 19.22 | X32: 19.23 | Y32: 19.24 | AB32: -1 | AC32: -2 | AD32: -2 | AE32: -1 | AF32: -2 | AG32: 2 | AH32: 1 | AI32: -1 | AJ32: 2 | AK32: 1 | AL32: -2 | AM32: -2 | AN32: 2 | AO32: 2 | AP32: -1 | AQ32: -1 | AR32: 1 | AS32: -2 | AT32: 1 | AU32: 2 | AV32: 1 | AW32: 2 | AX32: 1 | AY32: -1
A33: Weight 1 | B33: -2 | C33: -2 | D33: -2 | E33: -2 | F33: -2 | G33: -2 | H33: -1 | I33: -1 | J33: -1 | K33: -1 | L33: -1 | M33: -1 | N33: 1 | O33: 1 | P33: 1 | Q33: 1 | R33: 1 | S33: 1 | T33: 2 | U33: 2 | V33: 2 | W33: 2 | X33: 2 | Y33: 2 | AB33: 1 | AC33: 2 | AD33: 1 | AE33: 2 | AF33: 2 | AG33: -1 | AH33: -2 | AI33: -2 | AJ33: 1 | AK33: 2 | AL33: -1 | AM33: -1 | AN33: 1 | AO33: -2 | AP33: -2 | AQ33: 1 | AR33: 2 | AS33: 1 | AT33: -1 | AU33: -1 | AV33: -1 | AW33: -2 | AX33: -2 | AY33: 2
A34: Weight 2 | B34: -1 | C34: -1 | D34: 1 | E34: 1 | F34: 2 | G34: 2 | H34: -2 | I34: -2 | J34: 1 | K34: 1 | L34: 2 | M34: 2 | N34: -2 | O34: -2 | P34: -1 | Q34: -1 | R34: 2 | S34: 2 | T34: -2 | U34: -2 | V34: -1 | W34: -1 | X34: 1 | Y34: 1 | AB34: 2 | AC34: 1 | AD34: 2 | AE34: 1 | AF34: -1 | AG34: -2 | AH34: -1 | AI34: 1 | AJ34: -2 | AK34: -1 | AL34: 2 | AM34: 1 | AN34: -1 | AO34: 1 | AP34: 2 | AQ34: -2 | AR34: -2 | AS34: -1 | AT34: 2 | AU34: 1 | AV34: -2 | AW34: -1 | AX34: 2 | AY34: -2
A35: Weight 3 | B35: 1 | C35: 2 | D35: -1 | E35: 2 | F35: -1 | G35: 1 | H35: 1 | I35: 2 | J35: -2 | K35: 2 | L35: -2 | M35: 1 | N35: -1 | O35: 2 | P35: -2 | Q35: 2 | R35: -2 | S35: -1 | T35: -1 | U35: 1 | V35: -2 | W35: 1 | X35: -2 | Y35: -1
A36: Weight 4 | B36: 2 | C36: 1 | D36: 2 | E36: -1 | F36: 1 | G36: -1 | H36: 2 | I36: 1 | J36: 2 | K36: -2 | L36: 1 | M36: -2 | N36: 2 | O36: -1 | P36: 2 | Q36: -2 | R36: -1 | S36: -2 | T36: 1 | U36: -1 | V36: 1 | W36: -2 | X36: -1 | Y36: -2
AB37: Sorted heatmap with conditional formating on the color:
A38: Perm | B38: 19.2 | C38: 19.14 | D38: 19.04 | E38: 19.22 | F38: 19.19 | G38: 19.1 | H38: 19.21 | I38: 19.15 | J38: 19.16 | K38: 19.24 | L38: 19.02 | M38: 19.23 | N38: 19.06 | O38: 19.12 | P38: 19.13 | Q38: 19.09 | R38: 19.01 | S38: 19.05 | T38: 19.03 | U38: 19.11 | V38: 19.07 | W38: 19.08 | X38: 19.18 | Y38: 19.17 | AB38: 19.2 | AC38: 19.14 | AD38: 19.04 | AE38: 19.22 | AF38: 19.19 | AG38: 19.1 | AH38: 19.21 | AI38: 19.15 | AJ38: 19.16 | AK38: 19.24 | AL38: 19.02 | AM38: 19.23 | AN38: 19.06 | AO38: 19.12 | AP38: 19.13 | AQ38: 19.09 | AR38: 19.01 | AS38: 19.05 | AT38: 19.03 | AU38: 19.11 | AV38: 19.07 | AW38: 19.08 | AX38: 19.18 | AY38: 19.17
A39: Weight 1 | B39: 2 | C39: 1 | D39: -2 | E39: 2 | F39: 2 | G39: -1 | H39: 2 | I39: 1 | J39: 1 | K39: 2 | L39: -2 | M39: 2 | N39: -2 | O39: -1 | P39: 1 | Q39: -1 | R39: -2 | S39: -2 | T39: -2 | U39: -1 | V39: -1 | W39: -1 | X39: 1 | Y39: 1 | AB39: 2 | AC39: 1 | AD39: -2 | AE39: 2 | AF39: 2 | AG39: -1 | AH39: 2 | AI39: 1 | AJ39: 1 | AK39: 2 | AL39: -2 | AM39: 2 | AN39: -2 | AO39: -1 | AP39: 1 | AQ39: -1 | AR39: -2 | AS39: -2 | AT39: -2 | AU39: -1 | AV39: -1 | AW39: -1 | AX39: 1 | AY39: 1
A40: Weight 2 | B40: -2 | C40: -2 | D40: 1 | E40: -1 | F40: -2 | G40: 1 | H40: -1 | I40: -1 | J40: -1 | K40: 1 | L40: -1 | M40: 1 | N40: 2 | O40: 2 | P40: -2 | Q40: 1 | R40: -1 | S40: 2 | T40: 1 | U40: 2 | V40: -2 | W40: -2 | X40: 2 | Y40: 2 | AB40: -2 | AC40: -2 | AD40: 1 | AE40: -1 | AF40: -2 | AG40: 1 | AH40: -1 | AI40: -1 | AJ40: -1 | AK40: 1 | AL40: -1 | AM40: 1 | AN40: 2 | AO40: 2 | AP40: -2 | AQ40: 1 | AR40: -1 | AS40: 2 | AT40: 1 | AU40: 2 | AV40: -2 | AW40: -2 | AX40: 2 | AY40: 2
A41: Weight 3 | B41: 1 | C41: 2 | D41: 2 | E41: 1 | F41: -1 | G41: 2 | H41: -2 | I41: -2 | J41: 2 | K41: -1 | L41: 2 | M41: -2 | N41: 1 | O41: 1 | P41: -1 | Q41: -2 | R41: 1 | S41: -1 | T41: -1 | U41: -2 | V41: 1 | W41: 2 | X41: -1 | Y41: -2 | AB41: 1 | AC41: 2 | AD41: 2 | AE41: 1 | AF41: -1 | AG41: 2 | AH41: -2 | AI41: -2 | AJ41: 2 | AK41: -1 | AL41: 2 | AM41: -2 | AN41: 1 | AO41: 1 | AP41: -1 | AQ41: -2 | AR41: 1 | AS41: -1 | AT41: -1 | AU41: -2 | AV41: 1 | AW41: 2 | AX41: -1 | AY41: -2
A42: Weight 4 | B42: -1 | C42: -1 | D42: -1 | E42: -2 | F42: 1 | G42: -2 | H42: 1 | I42: 2 | J42: -2 | K42: -2 | L42: 1 | M42: -1 | N42: -1 | O42: -2 | P42: 2 | Q42: 2 | R42: 2 | S42: 1 | T42: 2 | U42: 1 | V42: 2 | W42: 1 | X42: -2 | Y42: -1 | AB42: -1 | AC42: -1 | AD42: -1 | AE42: -2 | AF42: 1 | AG42: -2 | AH42: 1 | AI42: 2 | AJ42: -2 | AK42: -2 | AL42: 1 | AM42: -1 | AN42: -1 | AO42: -2 | AP42: 2 | AQ42: 2 | AR42: 2 | AS42: 1 | AT42: 2 | AU42: 1 | AV42: 2 | AW42: 1 | AX42: -2 | AY42: -1

Sheet 19.01
A1: Input weights: | F1: B constant: | K1: No constant: | P1: P constant: | U1: PB constant:
A2: cols regulators/rows targets | B2: gene1 | C2: gene2 | D2: gene3 | F2: cols regulators/rows targets | G2: gene1 | H2: gene2 | I2: gene3 | K2: cols regulators/rows targets | L2: gene1 | M2: gene2 | N2: gene3 | P2: cols regulators/rows targets | Q2: gene1 | R2: gene2 | S2: gene3 | U2: cols regulators/rows targets | V2: gene1 | W2: gene2 | X2: gene3
A3: gene1 | B3: -2 | C3: 0 | D3: 0 | F3: gene1 | G3: -1.9999881 | H3: 0 | I3: 0 | K3: gene1 | L3: -1.8222714 | M3: 0 | N3: 0 | P3: gene1 | Q3: -1.9996161 | R3: 0 | S3: 0 | U3: gene1 | V3: -1.9999996 | W3: 0 | X3: 0
A4: gene2 | B4: 0 | C4: -1 | D4: 0 | F4: gene2 | G4: 0 | H4: -0.99994047 | I4: 0 | K4: gene2 | L4: 0 | M4: -0.87442255 | N4: 0 | P4: gene2 | Q4: 0 | R4: -0.99984043 | S4: 0 | U4: gene2 | V4: 0 | W4: -0.99999988 | X4: 0
A5: gene3 | B5: 2 | C5: 1 | D5: 0 | F5: gene3 | G5: 1.9998737 | H5: 0.99987924 | I5: 0 | K5: gene3 | L5: 0.65027116 | M5: 0.7207858 | N5: 0 | P5: gene3 | Q5: 1.9996339 | R5: 0.99992593 | S5: 0 | U5: gene3 | V5: 1.999999 | W5: 0.99999908 | X5: 0
F7: difference squared:
G8: =(G3-B3)^2 -> 1.4119073e-10 | H8: =(H3-C3)^2 -> 0 | I8: =(I3-D3)^2 -> 0 | L8: =(L3-B3)^2 -> 0.031587468 | M8: =(M3-C3)^2 -> 0 | N8: =(N3-D3)^2 -> 0 | Q8: =(Q3-B3)^2 -> 1.4738409e-07 | R8: =(R3-C3)^2 -> 0 | S8: =(S3-D3)^2 -> 0 | V8: =(V3-B3)^2 -> 1.9283323e-13 | W8: =(W3-C3)^2 -> 0 | X8: =(X3-D3)^2 -> 0
G9: =(G4-B4)^2 -> 0 | H9: =(H4-C4)^2 -> 3.5432652e-09 | I9: =(I4-D4)^2 -> 0 | L9: =(L4-B4)^2 -> 0 | M9: =(M4-C4)^2 -> 0.015769695 | N9: =(N4-D4)^2 -> 0 | Q9: =(Q4-B4)^2 -> 0 | R9: =(R4-C4)^2 -> 2.5462673e-08 | S9: =(S4-D4)^2 -> 0 | V9: =(V4-B4)^2 -> 0 | W9: =(W4-C4)^2 -> 1.5597325e-14 | X9: =(X4-D4)^2 -> 0
G10: =(G5-B5)^2 -> 1.5951428e-08 | H10: =(H5-C5)^2 -> 1.4583751e-08 | I10: =(I5-D5)^2 -> 0 | L10: =(L5-B5)^2 -> 1.821768 | M10: =(M5-C5)^2 -> 0.077960567 | N10: =(N5-D5)^2 -> 0 | Q10: =(Q5-B5)^2 -> 1.3399688e-07 | R10: =(R5-C5)^2 -> 5.4869913e-09 | S10: =(S5-D5)^2 -> 0 | V10: =(V5-B5)^2 -> 1.0323633e-12 | W10: =(W5-C5)^2 -> 8.4734982e-13 | X10: =(X5-D5)^2 -> 0
F12: sum:
G13: =SUM(G8:I10) -> 3.4219635e-08 | L13: =SUM(L8:N10) -> 1.9470857 | Q13: =SUM(Q8:S10) -> 3.1233063e-07 | V13: =SUM(V8:X10) -> 2.0881437e-12
A19: Making sure the expression data is good
A20: 15 | B20: 30 | C20: 60
A21: -0.91503905 | B21: -0.93939714 | C21: -0.9398715
A22: -0.54229869 | B22: -0.56653258 | C22: -0.56746433
A23: 0.73163825 | B23: 0.75948181 | C23: 0.76166262
A26: id | B26: 15 | C26: 15 | D26: 15 | E26: 15 | F26: 30 | G26: 30 | H26: 30 | I26: 30 | J26: 30 | K26: 60 | L26: 60 | M26: 60 | N26: 60
A27: gene1 | B27: -0.91503905 | C27: -0.91503905 | D27: -0.91503905 | E27: -0.91503905 | F27: -0.93939714 | G27: -0.93939714 | H27: -0.93939714 | I27: -0.93939714 | J27: -0.93939714 | K27: -0.9398715 | L27: -0.9398715 | M27: -0.9398715 | N27: -0.9398715
A28: gene2 | B28: -0.54229869 | C28: -0.54229869 | D28: -0.54229869 | E28: -0.54229869 | F28: -0.56653258 | G28: -0.56653258 | H28: -0.56653258 | I28: -0.56653258 | J28: -0.56653258 | K28: -0.56746433 | L28: -0.56746433 | M28: -0.56746433 | N28: -0.56746433
A29: gene3 | B29: 0.73163825 | C29: 0.73163825 | D29: 0.73163825 | E29: 0.73163825 | F29: 0.75948181 | G29: 0.75948181 | H29: 0.75948181 | I29: 0.75948181 | J29: 0.75948181 | K29: 0.76166262 | L29: 0.76166262 | M29: 0.76166262 | N29: 0.76166262
B31: =(B27-A21) -> -1.110223e-16 | C31: =(C27-A21) -> -1.110223e-16 | D31: =(D27-A21) -> -1.110223e-16 | E31: =(E27-A21) -> -1.110223e-16 | F31: =F27-B21 -> 0 | G31: =G27-B21 -> 0 | H31: =H27-B21 -> 0 | I31: =I27-B21 -> 0 | J31: =J27-B21 -> 0 | K31: =K27-C21 -> 0 | L31: =L27-C21 -> 0 | M31: =M27-C21 -> 0 | N31: =N27-C21 -> 0
B32: =(B28-A22) -> 4.4408921e-16 | C32: =(C28-A22) -> 4.4408921e-16 | D32: =(D28-A22) -> 4.4408921e-16 | E32: =(E28-A22) -> 4.4408921e-16 | F32: =F28-B22 -> 0 | G32: =G28-B22 -> 0 | H32: =H28-B22 -> 0 | I32: =I28-B22 -> 0 | J32: =J28-B22 -> 0 | K32: =K28-C22 -> 0 | L32: =L28-C22 -> 0 | M32: =M28-C22 -> 0 | N32: =N28-C22 -> 0
B33: =(B29-A23) -> 1.110223e-16 | C33: =(C29-A23) -> 1.110223e-16 | D33: =(D29-A23) -> 1.110223e-16 | E33: =(E29-A23) -> 1.110223e-16 | F33: =F29-B23 -> 0 | G33: =G29-B23 -> 0 | H33: =H29-B23 -> 0 | I33: =I29-B23 -> 0 | J33: =J29-B23 -> 0 | K33: =K29-C23 -> 0 | L33: =L29-C23 -> 0 | M33: =M29-C23 -> 0 | N33: =N29-C23 -> 0

Sheet 19.02
A1: Input weights: | F1: B constant: | K1: No constant: | P1: P constant: | U1: PB constant:
A2: cols regulators/rows targets | B2: gene1 | C2: gene2 | D2: gene3 | F2: cols regulators/rows targets | G2: gene1 | H2: gene2 | I2: gene3 | K2: cols regulators/rows targets | L2: gene1 | M2: gene2 | N2: gene3 | P2: cols regulators/rows targets | Q2: gene1 | R2: gene2 | S2: gene3 | U2: cols regulators/rows targets | V2: gene1 | W2: gene2 | X2: gene3
A3: gene1 | B3: -2 | C3: 0 | D3: 0 | F3: gene1 | G3: -1.9998186 | H3: 0 | I3: 0 | K3: gene1 | L3: -1.6154323 | M3: 0 | N3: 0 | P3: gene1 | Q3: -1.9997249 | R3: 0 | S3: 0 | U3: gene1 | V3: -1.9999997 | W3: 0 | X3: 0
A4: gene2 | B4: 0 | C4: 2 | D4: 0 | F4: gene2 | G4: 0 | H4: 1.9999008 | I4: 0 | K4: gene2 | L4: 0 | M4: 1.8228597 | N4: 0 | P4: gene2 | Q4: 0 | R4: 1.999912 | S4: 0 | U4: gene2 | V4: 0 | W4: 1.9999925 | X4: 0
A5: gene3 | B5: -1 | C5: 1 | D5: 0 | F5: gene3 | G5: -0.91675055 | H5: 0.50759645 | I5: 0 | K5: gene3 | L5: -0.65193961 | M5: 0.2742604 | N5: 0 | P5: gene3 | Q5: -0.99991495 | R5: 1.0000076 | S5: 0 | U5: gene3 | V5: -0.99998654 | W5: 0.99999632 | X5: 0
F7: difference squared:
G8: =(G3-B3)^2 -> 3.2891344e-08 | H8: =(H3-C3)^2 -> 0 | I8: =(I3-D3)^2 -> 0 | L8: =(L3-B3)^2 -> 0.14789229 | M8: =(M3-C3)^2 -> 0 | N8: =(N3-D3)^2 -> 0 | Q8: =(Q3-B3)^2 -> 7.5697309e-08 | R8: =(R3-C3)^2 -> 0 | S8: =(S3-D3)^2 -> 0 | V8: =(V3-B3)^2 -> 9.4938862e-14 | W8: =(W3-C3)^2 -> 0 | X8: =(X3-D3)^2 -> 0
G9: =(G4-B4)^2 -> 0 | H9: =(H4-C4)^2 -> 9.8385513e-09 | I9: =(I4-D4)^2 -> 0 | L9: =(L4-B4)^2 -> 0 | M9: =(M4-C4)^2 -> 0.031378681 | N9: =(N4-D4)^2 -> 0 | Q9: =(Q4-B4)^2 -> 0 | R9: =(R4-C4)^2 -> 7.7473883e-09 | S9: =(S4-D4)^2 -> 0 | V9: =(V4-B4)^2 -> 0 | W9: =(W4-C4)^2 -> 5.6994788e-11 | X9: =(X4-D4)^2 -> 0
G10: =(G5-B5)^2 -> 0.0069304703 | H10: =(H5-C5)^2 -> 0.24246126 | I10: =(I5-D5)^2 -> 0 | L10: =(L5-B5)^2 -> 0.12114604 | M10: =(M5-C5)^2 -> 0.52669796 | N10: =(N5-D5)^2 -> 0 | Q10: =(Q5-B5)^2 -> 7.2329816e-09 | R10: =(R5-C5)^2 -> 5.8277747e-11 | S10: =(S5-D5)^2 -> 0 | V10: =(V5-B5)^2 -> 1.8114637e-10 | W10: =(W5-C5)^2 -> 1.3571661e-11 | X10: =(X5-D5)^2 -> 0
F12: sum:
G13: =SUM(G8:I10) -> 0.24939177 | L13: =SUM(L8:N10) -> 0.82711497 | Q13: =SUM(Q8:S10) -> 9.0735957e-08 | V13: =SUM(V8:X10) -> 2.5180776e-10
A19: Making sure the expression data is good
A20: 15 | B20: 30 | C20: 60
A21: -0.91500207 | B21: -0.93939739 | C21: -0.9398715
A22: 0.87472995 | B22: 0.96025227 | C22: 0.97145734
A23: 0.52698988 | B23: 0.66774924 | C23: 0.69258795
A26: id | B26: 15 | C26: 15 | D26: 15 | E26: 15 | F26: 30 | G26: 30 | H26: 30 | I26: 30 | J26: 30 | K26: 60 | L26: 60 | M26: 60 | N26: 60
A27: gene1 | B27: -0.91500207 | C27: -0.91500207 | D27: -0.91500207 | E27: -0.91500207 | F27: -0.93939739 | G27: -0.93939739 | H27: -0.93939739 | I27: -0.93939739 | J27: -0.93939739 | K27: -0.9398715 | L27: -0.9398715 | M27: -0.9398715 | N27: -0.9398715
A28: gene2 | B28: 0.87472995 | C28: 0.87472995 | D28: 0.87472995 | E28: 0.87472995 | F28: 0.96025227 | G28: 0.96025227 | H28: 0.96025227 | I28: 0.96025227 | J28: 0.96025227 | K28: 0.97145734 | L28: 0.97145734 | M28: 0.97145734 | N28: 0.97145734
A29: gene3 | B29: 0.52698988 | C29: 0.52698988 | D29: 0.52698988 | E29: 0.52698988 | F29: 0.66774924 | G29: 0.66774924 | H29: 0.66774924 | I29: 0.66774924 | J29: 0.66774924 | K29: 0.69258795 | L29: 0.69258795 | M29: 0.69258795 | N29: 0.69258795
B31: =(B27-A21) -> 2.220446e-16 | C31: =(C27-A21) -> 2.220446e-16 | D31: =(D27-A21) -> 2.220446e-16 | E31: =(E27-A21) -> 2.220446e-16 | F31: =F27-B21 -> 0 | G31: =G27-B21 -> 0 | H31: =H27-B21 -> 0 | I31: =I27-B21 -> 0 | J31: =J27-B21 -> 0 | K31: =K27-C21 -> 0 | L31: =L27-C21 -> 0 | M31: =M27-C21 -> 0 | N31: =N27-C21 -> 0
B32: =(B28-A22) -> -2.220446e-16 | C32: =(C28-A22) -> -2.220446e-16 | D32: =(D28-A22) -> -2.220446e-16 | E32: =(E28-A22) -> -2.220446e-16 | F32: =F28-B22 -> 0 | G32: =G28-B22 -> 0 | H32: =H28-B22 -> 0 | I32: =I28-B22 -> 0 | J32: =J28-B22 -> 0 | K32: =K28-C22 -> 0 | L32: =L28-C22 -> 0 | M32: =M28-C22 -> 0 | N32: =N28-C22 -> 0
B33: =(B29-A23) -> 1.110223e-16 | C33: =(C29-A23) -> 1.110223e-16 | D33: =(D29-A23) -> 1.110223e-16 | E33: =(E29-A23) -> 1.110223e-16 | F33: =F29-B23 -> 0 | G33: =G29-B23 -> 0 | H33: =H29-B23 -> 0 | I33: =I29-B23 -> 0 | J33: =J29-B23 -> 0 | K33: =K29-C23 -> 0 | L33: =L29-C23 -> 0 | M33: =M29-C23 -> 0 | N33: =N29-C23 -> 0

Sheet 19.03
A1: Input weights: | F1: B constant: | K1: No constant: | P1: P constant: | U1: PB constant:
A2: cols regulators/rows targets | B2: gene1 | C2: gene2 | D2: gene3 | F2: cols regulators/rows targets | G2: gene1 | H2: gene2 | I2: gene3 | K2: cols regulators/rows targets | L2: gene1 | M2: gene2 | N2: gene3 | P2: cols regulators/rows targets | Q2: gene1 | R2: gene2 | S2: gene3 | U2: cols regulators/rows targets | V2: gene1 | W2: gene2 | X2: gene3
A3: gene1 | B3: -2 | C3: 0 | D3: 0 | F3: gene1 | G3: -1.9999999 | H3: 0 | I3: 0 | K3: gene1 | L3: -1.7623394 | M3: 0 | N3: 0 | P3: gene1 | Q3: -1.9996582 | R3: 0 | S3: 0 | U3: gene1 | V3: -1.9999996 | W3: 0 | X3: 0
A4: gene2 | B4: 0 | C4: -1 | D4: 0 | F4: gene2 | G4: 0 | H4: -0.99993541 | I4: 0 | K4: gene2 | L4: 0 | M4: -0.8740603 | N4: 0 | P4: gene2 | Q4: 0 | R4: -0.99985761 | S4: 0 | U4: gene2 | V4: 0 | W4: -0.99999986 | X4: 0
A5: gene3 | B5: 1 | C5: 2 | D5: 0 | F5: gene3 | G5: 0.99990544 | H5: 1.9998457 | I5: 0 | K5: gene3 | L5: 0.12229715 | M5: 0.68151042 | N5: 0 | P5: gene3 | Q5: 0.99991126 | R5: 1.99972 | S5: 0 | U5: gene3 | V5: 0.99999916 | W5: 1.9999987 | X5: 0
F7: difference squared:
G8: =(G3-B3)^2 -> 8.1323517e-15 | H8: =(H3-C3)^2 -> 0 | I8: =(I3-D3)^2 -> 0 | L8: =(L3-B3)^2 -> 0.056482563 | M8: =(M3-C3)^2 -> 0 | N8: =(N3-D3)^2 -> 0 | Q8: =(Q3-B3)^2 -> 1.1681497e-07 | R8: =(R3-C3)^2 -> 0 | S8: =(S3-D3)^2 -> 0 | V8: =(V3-B3)^2 -> 1.4848739e-13 | W8: =(W3-C3)^2 -> 0 | X8: =(X3-D3)^2 -> 0
G9: =(G4-B4)^2 -> 0 | H9: =(H4-C4)^2 -> 4.1715368e-09 | I9: =(I4-D4)^2 -> 0 | L9: =(L4-B4)^2 -> 0 | M9: =(M4-C4)^2 -> 0.015860809 | N9: =(N4-D4)^2 -> 0 | Q9: =(Q4-B4)^2 -> 0 | R9: =(R4-C4)^2 -> 2.0274797e-08 | S9: =(S4-D4)^2 -> 0 | V9: =(V4-B4)^2 -> 0 | W9: =(W4-C4)^2 -> 1.9966666e-14 | X9: =(X4-D4)^2 -> 0
G10: =(G5-B5)^2 -> 8.9411649e-09 | H10: =(H5-C5)^2 -> 2.3810398e-08 | I10: =(I5-D5)^2 -> 0 | L10: =(L5-B5)^2 -> 0.77036229 | M10: =(M5-C5)^2 -> 1.7384148 | N10: =(N5-D5)^2 -> 0 | Q10: =(Q5-B5)^2 -> 7.8742737e-09 | R10: =(R5-C5)^2 -> 7.8388992e-08 | S10: =(S5-D5)^2 -> 0 | V10: =(V5-B5)^2 -> 7.0220497e-13 | W10: =(W5-C5)^2 -> 1.6833194e-12 | X10: =(X5-D5)^2 -> 0
F12: sum:
G13: =SUM(G8:I10) -> 3.6923107e-08 | L13: =SUM(L8:N10) -> 2.5811204 | Q13: =SUM(Q8:S10) -> 2.2335303e-07 | V13: =SUM(V8:X10) -> 2.5539784e-12
A19: Making sure the expression data is good
A20: 15 | B20: 30 | C20: 60
A21: -0.91503905 | B21: -0.93939714 | C21: -0.9398715
A22: -0.54229869 | B22: -0.56653258 | C22: -0.56746433
A23: 0.756586 | B23: 0.79046629 | C23: 0.79325311
A26: id | B26: 15 | C26: 15 | D26: 15 | E26: 15 | F26: 30 | G26: 30 | H26: 30 | I26: 30 | J26: 30 | K26: 60 | L26: 60 | M26: 60 | N26: 60
A27: gene1 | B27: -0.91503905 | C27: -0.91503905 | D27: -0.91503905 | E27: -0.91503905 | F27: -0.93939714 | G27: -0.93939714 | H27: -0.93939714 | I27: -0.93939714 | J27: -0.93939714 | K27: -0.9398715 | L27: -0.9398715 | M27: -0.9398715 | N27: -0.9398715
A28: gene2 | B28: -0.54229869 | C28: -0.54229869 | D28: -0.54229869 | E28: -0.54229869 | F28: -0.56653258 | G28: -0.56653258 | H28: -0.56653258 | I28: -0.56653258 | J28: -0.56653258 | K28: -0.56746433 | L28: -0.56746433 | M28: -0.56746433 | N28: -0.56746433
A29: gene3 | B29: 0.756586 | C29: 0.756586 | D29: 0.756586 | E29: 0.756586 | F29: 0.79046629 | G29: 0.79046629 | H29: 0.79046629 | I29: 0.79046629 | J29: 0.79046629 | K29: 0.79325311 | L29: 0.79325311 | M29: 0.79325311 | N29: 0.79325311
B31: =(B27-A21) -> -1.110223e-16 | C31: =(C27-A21) -> -1.110223e-16 | D31: =(D27-A21) -> -1.110223e-16 | E31: =(E27-A21) -> -1.110223e-16 | F31: =F27-B21 -> 0 | G31: =G27-B21 -> 0 | H31: =H27-B21 -> 0 | I31: =I27-B21 -> 0 | J31: =J27-B21 -> 0 | K31: =K27-C21 -> 0 | L31: =L27-C21 -> 0 | M31: =M27-C21 -> 0 | N31: =N27-C21 -> 0
B32: =(B28-A22) -> 4.4408921e-16 | C32: =(C28-A22) -> 4.4408921e-16 | D32: =(D28-A22) -> 4.4408921e-16 | E32: =(E28-A22) -> 4.4408921e-16 | F32: =F28-B22 -> 0 | G32: =G28-B22 -> 0 | H32: =H28-B22 -> 0 | I32: =I28-B22 -> 0 | J32: =J28-B22 -> 0 | K32: =K28-C22 -> 0 | L32: =L28-C22 -> 0 | M32: =M28-C22 -> 0 | N32: =N28-C22 -> 0
B33: =(B29-A23) -> -2.220446e-16 | C33: =(C29-A23) -> -2.220446e-16 | D33: =(D29-A23) -> -2.220446e-16 | E33: =(E29-A23) -> -2.220446e-16 | F33: =F29-B23 -> 0 | G33: =G29-B23 -> 0 | H33: =H29-B23 -> 0 | I33: =I29-B23 -> 0 | J33: =J29-B23 -> 0 | K33: =K29-C23 -> 0 | L33: =L29-C23 -> 0 | M33: =M29-C23 -> 0 | N33: =N29-C23 -> 0

Sheet 19.04
A1: Input weights: | F1: B constant: | K1: No constant: | P1: P constant: | U1: PB constant:
A2: cols regulators/rows targets | B2: gene1 | C2: gene2 | D2: gene3 | F2: cols regulators/rows targets | G2: gene1 | H2: gene2 | I2: gene3 | K2: cols regulators/rows targets | L2: gene1 | M2: gene2 | N2: gene3 | P2: cols regulators/rows targets | Q2: gene1 | R2: gene2 | S2: gene3 | U2: cols regulators/rows targets | V2: gene1 | W2: gene2 | X2: gene3
A3: gene1 | B3: -2 | C3: 0 | D3: 0 | F3: gene1 | G3: -7.0767132 | H3: 0 | I3: 0 | K3: gene1 | L3: -1.8326718 | M3: 0 | N3: 0 | P3: gene1 | Q3: -1.999993 | R3: 0 | S3: 0 | U3: gene1 | V3: -1.9999998 | W3: 0 | X3: 0
A4: gene2 | B4: 0 | C4: 2 | D4: 0 | F4: gene2 | G4: 0 | H4: 2.2460096 | I4: 0 | K4: gene2 | L4: 0 | M4: 1.9576147 | N4: 0 | P4: gene2 | Q4: 0 | R4: 1.9999933 | S4: 0 | U4: gene2 | V4: 0 | W4: 1.9999918 | X4: 0
A5: gene3 | B5: 1 | C5: -1 | D5: 0 | F5: gene3 | G5: -2.1455906 | H5: -1.251093 | I5: 0 | K5: gene3 | L5: 0.6407678 | M5: -0.87912519 | N5: 0 | P5: gene3 | Q5: 0.99999458 | R5: -0.99999791 | S5: 0 | U5: gene3 | V5: 0.99999417 | W5: -0.99999874 | X5: 0
F7: difference squared:
G8: =(G3-B3)^2 -> 25.773017 | H8: =(H3-C3)^2 -> 0 | I8: =(I3-D3)^2 -> 0 | L8: =(L3-B3)^2 -> 0.027998723 | M8: =(M3-C3)^2 -> 0 | N8: =(N3-D3)^2 -> 0 | Q8: =(Q3-B3)^2 -> 4.8698867e-11 | R8: =(R3-C3)^2 -> 0 | S8: =(S3-D3)^2 -> 0 | V8: =(V3-B3)^2 -> 5.9875586e-14 | W8: =(W3-C3)^2 -> 0 | X8: =(X3-D3)^2 -> 0
G9: =(G4-B4)^2 -> 0 | H9: =(H4-C4)^2 -> 0.060520722 | I9: =(I4-D4)^2 -> 0 | L9: =(L4-B4)^2 -> 0 | M9: =(M4-C4)^2 -> 0.001796514 | N9: =(N4-D4)^2 -> 0 | Q9: =(Q4-B4)^2 -> 0 | R9: =(R4-C4)^2 -> 4.5182175e-11 | S9: =(S4-D4)^2 -> 0 | V9: =(V4-B4)^2 -> 0 | W9: =(W4-C4)^2 -> 6.7437305e-11 | X9: =(X4-D4)^2 -> 0
G10: =(G5-B5)^2 -> 9.8947402 | H10: =(H5-C5)^2 -> 0.063047706 | I10: =(I5-D5)^2 -> 0 | L10: =(L5-B5)^2 -> 0.12904778 | M10: =(M5-C5)^2 -> 0.014610719 | N10: =(N5-D5)^2 -> 0 | Q10: =(Q5-B5)^2 -> 2.9330611e-11 | R10: =(R5-C5)^2 -> 4.3608583e-12 | S10: =(S5-D5)^2 -> 0 | V10: =(V5-B5)^2 -> 3.4043518e-11 | W10: =(W5-C5)^2 -> 1.5890916e-12 | X10: =(X5-D5)^2 -> 0
F12: sum:
G13: =SUM(G8:I10) -> 35.791326 | L13: =SUM(L8:N10) -> 0.17345373 | Q13: =SUM(Q8:S10) -> 1.2757251e-10 | V13: =SUM(V8:X10) -> 1.0312979e-10
A19: Making sure the expression data is good
A20: 15 | B20: 30 | C20: 60
A21: -0.91500207 | B21: -0.93939739 | C21: -0.9398715
A22: 0.87472995 | B22: 0.96025227 | C22: 0.97145734
A23: -0.83917547 | B23: -1.2818137 | C23: -1.3819891
A26: id | B26: 15 | C26: 15 | D26: 15 | E26: 15 | F26: 30 | G26: 30 | H26: 30 | I26: 30 | J26: 30 | K26: 60 | L26: 60 | M26: 60 | N26: 60
A27: gene1 | B27: -0.91500207 | C27: -0.91500207 | D27: -0.91500207 | E27: -0.91500207 | F27: -0.93939739 | G27: -0.93939739 | H27: -0.93939739 | I27: -0.93939739 | J27: -0.93939739 | K27: -0.9398715 | L27: -0.9398715 | M27: -0.9398715 | N27: -0.9398715
A28: gene2 | B28: 0.87472995 | C28: 0.87472995 | D28: 0.87472995 | E28: 0.87472995 | F28: 0.96025227 | G28: 0.96025227 | H28: 0.96025227 | I28: 0.96025227 | J28: 0.96025227 | K28: 0.97145734 | L28: 0.97145734 | M28: 0.97145734 | N28: 0.97145734
A29: gene3 | B29: -0.83917547 | C29: -0.83917547 | D29: -0.83917547 | E29: -0.83917547 | F29: -1.2818137 | G29: -1.2818137 | H29: -1.2818137 | I29: -1.2818137 | J29: -1.2818137 | K29: -1.3819891 | L29: -1.3819891 | M29: -1.3819891 | N29: -1.3819891
B31: =(B27-A21) -> 2.220446e-16 | C31: =(C27-A21) -> 2.220446e-16 | D31: =(D27-A21) -> 2.220446e-16 | E31: =(E27-A21) -> 2.220446e-16 | F31: =F27-B21 -> 0 | G31: =G27-B21 -> 0 | H31: =H27-B21 -> 0 | I31: =I27-B21 -> 0 | J31: =J27-B21 -> 0 | K31: =K27-C21 -> 0 | L31: =L27-C21 -> 0 | M31: =M27-C21 -> 0 | N31: =N27-C21 -> 0
B32: =(B28-A22) -> -2.220446e-16 | C32: =(C28-A22) -> -2.220446e-16 | D32: =(D28-A22) -> -2.220446e-16 | E32: =(E28-A22) -> -2.220446e-16 | F32: =F28-B22 -> 0 | G32: =G28-B22 -> 0 | H32: =H28-B22 -> 0 | I32: =I28-B22 -> 0 | J32: =J28-B22 -> 0 | K32: =K28-C22 -> 0 | L32: =L28-C22 -> 0 | M32: =M28-C22 -> 0 | N32: =N28-C22 -> 0
B33: =(B29-A23) -> 2.220446e-16 | C33: =(C29-A23) -> 2.220446e-16 | D33: =(D29-A23) -> 2.220446e-16 | E33: =(E29-A23) -> 2.220446e-16 | F33: =F29-B23 -> -4.4408921e-15 | G33: =G29-B23 -> -4.4408921e-15 | H33: =H29-B23 -> -4.4408921e-15 | I33: =I29-B23 -> -4.4408921e-15 | J33: =J29-B23 -> -4.4408921e-15 | K33: =K29-C23 -> 0 | L33: =L29-C23 -> 0 | M33: =M29-C23 -> 0 | N33: =N29-C23 -> 0

Sheet 19.05
A1: Input weights: | F1: B constant: | K1: No constant: | P1: P constant: | U1: PB constant:
A2: cols regulators/rows targets | B2: gene1 | C2: gene2 | D2: gene3 | F2: cols regulators/rows targets | G2: gene1 | H2: gene2 | I2: gene3 | K2: cols regulators/rows targets | L2: gene1 | M2: gene2 | N2: gene3 | P2: cols regulators/rows targets | Q2: gene1 | R2: gene2 | S2: gene3 | U2: cols regulators/rows targets | V2: gene1 | W2: gene2 | X2: gene3
A3: gene1 | B3: -2 | C3: 0 | D3: 0 | F3: gene1 | G3: -1.9999881 | H3: 0 | I3: 0 | K3: gene1 | L3: -1.8222714 | M3: 0 | N3: 0 | P3: gene1 | Q3: -1.9996161 | R3: 0 | S3: 0 | U3: gene1 | V3: -1.9999996 | W3: 0 | X3: 0
A4: gene2 | B4: 0 | C4: -1 | D4: 0 | F4: gene2 | G4: 0 | H4: -0.99994047 | I4: 0 | K4: gene2 | L4: 0 | M4: -0.87442255 | N4: 0 | P4: gene2 | Q4: 0 | R4: -0.99984043 | S4: 0 | U4: gene2 | V4: 0 | W4: -0.99999988 | X4: 0
A5: gene3 | B5: 2 | C5: 1 | D5: 0 | F5: gene3 | G5: 1.9998737 | H5: 0.99987924 | I5: 0 | K5: gene3 | L5: 0.65027116 | M5: 0.7207858 | N5: 0 | P5: gene3 | Q5: 1.9996339 | R5: 0.99992593 | S5: 0 | U5: gene3 | V5: 1.999999 | W5: 0.99999908 | X5: 0
F7: difference squared:
G8: =(G3-B3)^2 -> 1.4119073e-10 | H8: =(H3-C3)^2 -> 0 | I8: =(I3-D3)^2 -> 0 | L8: =(L3-B3)^2 -> 0.031587468 | M8: =(M3-C3)^2 -> 0 | N8: =(N3-D3)^2 -> 0 | Q8: =(Q3-B3)^2 -> 1.4738409e-07 | R8: =(R3-C3)^2 -> 0 | S8: =(S3-D3)^2 -> 0 | V8: =(V3-B3)^2 -> 1.9283323e-13 | W8: =(W3-C3)^2 -> 0 | X8: =(X3-D3)^2 -> 0
G9: =(G4-B4)^2 -> 0 | H9: =(H4-C4)^2 -> 3.5432652e-09 | I9: =(I4-D4)^2 -> 0 | L9: =(L4-B4)^2 -> 0 | M9: =(M4-C4)^2 -> 0.015769695 | N9: =(N4-D4)^2 -> 0 | Q9: =(Q4-B4)^2 -> 0 | R9: =(R4-C4)^2 -> 2.5462673e-08 | S9: =(S4-D4)^2 -> 0 | V9: =(V4-B4)^2 -> 0 | W9: =(W4-C4)^2 -> 1.5597325e-14 | X9: =(X4-D4)^2 -> 0
G10: =(G5-B5)^2 -> 1.5951428e-08 | H10: =(H5-C5)^2 -> 1.4583751e-08 | I10: =(I5-D5)^2 -> 0 | L10: =(L5-B5)^2 -> 1.821768 | M10: =(M5-C5)^2 -> 0.077960567 | N10: =(N5-D5)^2 -> 0 | Q10: =(Q5-B5)^2 -> 1.3399688e-07 | R10: =(R5-C5)^2 -> 5.4869913e-09 | S10: =(S5-D5)^2 -> 0 | V10: =(V5-B5)^2 -> 1.0323633e-12 | W10: =(W5-C5)^2 -> 8.4734982e-13 | X10: =(X5-D5)^2 -> 0
F12: sum:
G13: =SUM(G8:I10) -> 3.4219635e-08 | L13: =SUM(L8:N10) -> 1.9470857 | Q13: =SUM(Q8:S10) -> 3.1233063e-07 | V13: =SUM(V8:X10) -> 2.0881437e-12
A19: Making sure the expression data is good
A20: 15 | B20: 30 | C20: 60
A21: -0.91503905 | B21: -0.93939714 | C21: -0.9398715
A22: -0.54229869 | B22: -0.56653258 | C22: -0.56746433
A23: 0.73163825 | B23: 0.75948181 | C23: 0.76166262
A26: id | B26: 15 | C26: 15 | D26: 15 | E26: 15 | F26: 30 | G26: 30 | H26: 30 | I26: 30 | J26: 30 | K26: 60 | L26: 60 | M26: 60 | N26: 60
A27: gene1 | B27: -0.91503905 | C27: -0.91503905 | D27: -0.91503905 | E27: -0.91503905 | F27: -0.93939714 | G27: -0.93939714 | H27: -0.93939714 | I27: -0.93939714 | J27: -0.93939714 | K27: -0.9398715 | L27: -0.9398715 | M27: -0.9398715 | N27: -0.9398715
A28: gene2 | B28: -0.54229869 | C28: -0.54229869 | D28: -0.54229869 | E28: -0.54229869 | F28: -0.56653258 | G28: -0.56653258 | H28: -0.56653258 | I28: -0.56653258 | J28: -0.56653258 | K28: -0.56746433 | L28: -0.56746433 | M28: -0.56746433 | N28: -0.56746433
A29: gene3 | B29: 0.73163825 | C29: 0.73163825 | D29: 0.73163825 | E29: 0.73163825 | F29: 0.75948181 | G29: 0.75948181 | H29: 0.75948181 | I29: 0.75948181 | J29: 0.75948181 | K29: 0.76166262 | L29: 0.76166262 | M29: 0.76166262 | N29: 0.76166262
B31: =(B27-A21) -> -1.110223e-16 | C31: =(C27-A21) -> -1.110223e-16 | D31: =(D27-A21) -> -1.110223e-16 | E31: =(E27-A21) -> -1.110223e-16 | F31: =F27-B21 -> 0 | G31: =G27-B21 -> 0 | H31: =H27-B21 -> 0 | I31: =I27-B21 -> 0 | J31: =J27-B21 -> 0 | K31: =K27-C21 -> 0 | L31: =L27-C21 -> 0 | M31: =M27-C21 -> 0 | N31: =N27-C21 -> 0
B32: =(B28-A22) -> 4.4408921e-16 | C32: =(C28-A22) -> 4.4408921e-16 | D32: =(D28-A22) -> 4.4408921e-16 | E32: =(E28-A22) -> 4.4408921e-16 | F32: =F28-B22 -> 0 | G32: =G28-B22 -> 0 | H32: =H28-B22 -> 0 | I32: =I28-B22 -> 0 | J32: =J28-B22 -> 0 | K32: =K28-C22 -> 0 | L32: =L28-C22 -> 0 | M32: =M28-C22 -> 0 | N32: =N28-C22 -> 0
B33: =(B29-A23) -> 1.110223e-16 | C33: =(C29-A23) -> 1.110223e-16 | D33: =(D29-A23) -> 1.110223e-16 | E33: =(E29-A23) -> 1.110223e-16 | F33: =F29-B23 -> 0 | G33: =G29-B23 -> 0 | H33: =H29-B23 -> 0 | I33: =I29-B23 -> 0 | J33: =J29-B23 -> 0 | K33: =K29-C23 -> 0 | L33: =L29-C23 -> 0 | M33: =M29-C23 -> 0 | N33: =N29-C23 -> 0

Sheet 19.06
A1: Input weights: | F1: B constant: | K1: No constant: | P1: P constant: | U1: PB constant:
A2: cols regulators/rows targets | B2: gene1 | C2: gene2 | D2: gene3 | F2: cols regulators/rows targets | G2: gene1 | H2: gene2 | I2: gene3 | K2: cols regulators/rows targets | L2: gene1 | M2: gene2 | N2: gene3 | P2: cols regulators/rows targets | Q2: gene1 | R2: gene2 | S2: gene3 | U2: cols regulators/rows targets | V2: gene1 | W2: gene2 | X2: gene3
A3: gene1 | B3: -2 | C3: 0 | D3: 0 | F3: gene1 | G3: -2.0005084 | H3: 0 | I3: 0 | K3: gene1 | L3: -1.5588657 | M3: 0 | N3: 0 | P3: gene1 | Q3: -1.9996736 | R3: 0 | S3: 0 | U3: gene1 | V3: -1.9999996 | W3: 0 | X3: 0
A4: gene2 | B4: 0 | C4: 1 | D4: 0 | F4: gene2 | G4: 0 | H4: 1.0053823 | I4: 0 | K4: gene2 | L4: 0 | M4: 0.97514373 | N4: 0 | P4: gene2 | Q4: 0 | R4: 1.0000074 | S4: 0 | U4: gene2 | V4: 0 | W4: 1.0000001 | X4: 0
A5: gene3 | B5: 2 | C5: -1 | D5: 0 | F5: gene3 | G5: 1.900428 | H5: -0.9948514 | I5: 0 | K5: gene3 | L5: 1.1758427 | M5: -0.78670313 | N5: 0 | P5: gene3 | Q5: 1.9997736 | R5: -1.0000046 | S5: 0 | U5: gene3 | V5: 1.9999794 | W5: -0.99999314 | X5: 0
F7: difference squared:
G8: =(G3-B3)^2 -> 2.5846868e-07 | H8: =(H3-C3)^2 -> 0 | I8: =(I3-D3)^2 -> 0 | L8: =(L3-B3)^2 -> 0.19459945 | M8: =(M3-C3)^2 -> 0 | N8: =(N3-D3)^2 -> 0 | Q8: =(Q3-B3)^2 -> 1.0652852e-07 | R8: =(R3-C3)^2 -> 0 | S8: =(S3-D3)^2 -> 0 | V8: =(V3-B3)^2 -> 1.3051463e-13 | W8: =(W3-C3)^2 -> 0 | X8: =(X3-D3)^2 -> 0
G9: =(G4-B4)^2 -> 0 | H9: =(H4-C4)^2 -> 2.8969463e-05 | I9: =(I4-D4)^2 -> 0 | L9: =(L4-B4)^2 -> 0 | M9: =(M4-C4)^2 -> 0.00061783413 | N9: =(N4-D4)^2 -> 0 | Q9: =(Q4-B4)^2 -> 0 | R9: =(R4-C4)^2 -> 5.42464e-11 | S9: =(S4-D4)^2 -> 0 | V9: =(V4-B4)^2 -> 0 | W9: =(W4-C4)^2 -> 1.2544107e-14 | X9: =(X4-D4)^2 -> 0
G10: =(G5-B5)^2 -> 0.009914591 | H10: =(H5-C5)^2 -> 2.6508084e-05 | I10: =(I5-D5)^2 -> 0 | L10: =(L5-B5)^2 -> 0.67923517 | M10: =(M5-C5)^2 -> 0.045495554 | N10: =(N5-D5)^2 -> 0 | Q10: =(Q5-B5)^2 -> 5.1268053e-08 | R10: =(R5-C5)^2 -> 2.1026431e-11 | S10: =(S5-D5)^2 -> 0 | V10: =(V5-B5)^2 -> 4.2526017e-10 | W10: =(W5-C5)^2 -> 4.7096721e-11 | X10: =(X5-D5)^2 -> 0
F12: sum:
G13: =SUM(G8:I10) -> 0.009970327 | L13: =SUM(L8:N10) -> 0.91994801 | Q13: =SUM(Q8:S10) -> 1.5787184e-07 | V13: =SUM(V8:X10) -> 4.7249995e-10
A19: Making sure the expression data is good
A20: 15 | B20: 30 | C20: 60
A21: -0.91503956 | B21: -0.9393975 | C21: -0.9398715
A22: 0.63369943 | B22: 0.7332098 | C22: 0.75435866
A23: -0.18253677 | B23: -0.45750708 | C23: -0.53627179
A26: id | B26: 15 | C26: 15 | D26: 15 | E26: 15 | F26: 30 | G26: 30 | H26: 30 | I26: 30 | J26: 30 | K26: 60 | L26: 60 | M26: 60 | N26: 60
A27: gene1 | B27: -0.91503956 | C27: -0.91503956 | D27: -0.91503956 | E27: -0.91503956 | F27: -0.9393975 | G27: -0.9393975 | H27: -0.9393975 | I27: -0.9393975 | J27: -0.9393975 | K27: -0.9398715 | L27: -0.9398715 | M27: -0.9398715 | N27: -0.9398715
A28: gene2 | B28: 0.63369943 | C28: 0.63369943 | D28: 0.63369943 | E28: 0.63369943 | F28: 0.7332098 | G28: 0.7332098 | H28: 0.7332098 | I28: 0.7332098 | J28: 0.7332098 | K28: 0.75435866 | L28: 0.75435866 | M28: 0.75435866 | N28: 0.75435866
A29: gene3 | B29: -0.18253677 | C29: -0.18253677 | D29: -0.18253677 | E29: -0.18253677 | F29: -0.45750708 | G29: -0.45750708 | H29: -0.45750708 | I29: -0.45750708 | J29: -0.45750708 | K29: -0.53627179 | L29: -0.53627179 | M29: -0.53627179 | N29: -0.53627179
B31: =(B27-A21) -> -3.3306691e-16 | C31: =(C27-A21) -> -3.3306691e-16 | D31: =(D27-A21) -> -3.3306691e-16 | E31: =(E27-A21) -> -3.3306691e-16 | F31: =F27-B21 -> 0 | G31: =G27-B21 -> 0 | H31: =H27-B21 -> 0 | I31: =I27-B21 -> 0 | J31: =J27-B21 -> 0 | K31: =K27-C21 -> 0 | L31: =L27-C21 -> 0 | M31: =M27-C21 -> 0 | N31: =N27-C21 -> 0
B32: =(B28-A22) -> -1.110223e-16 | C32: =(C28-A22) -> -1.110223e-16 | D32: =(D28-A22) -> -1.110223e-16 | E32: =(E28-A22) -> -1.110223e-16 | F32: =F28-B22 -> 0 | G32: =G28-B22 -> 0 | H32: =H28-B22 -> 0 | I32: =I28-B22 -> 0 | J32: =J28-B22 -> 0 | K32: =K28-C22 -> 0 | L32: =L28-C22 -> 0 | M32: =M28-C22 -> 0 | N32: =N28-C22 -> 0
B33: =(B29-A23) -> -2.7755576e-16 | C33: =(C29-A23) -> -2.7755576e-16 | D33: =(D29-A23) -> -2.7755576e-16 | E33: =(E29-A23) -> -2.7755576e-16 | F33: =F29-B23 -> 0 | G33: =G29-B23 -> 0 | H33: =H29-B23 -> 0 | I33: =I29-B23 -> 0 | J33: =J29-B23 -> 0 | K33: =K29-C23 -> 0 | L33: =L29-C23 -> 0 | M33: =M29-C23 -> 0 | N33: =N29-C23 -> 0

Sheet 19.07
A1: Input weights: | F1: B constant: | K1: No constant: | P1: P constant: | U1: PB constant:
A2: cols regulators/rows targets | B2: gene1 | C2: gene2 | D2: gene3 | F2: cols regulators/rows targets | G2: gene1 | H2: gene2 | I2: gene3 | K2: cols regulators/rows targets | L2: gene1 | M2: gene2 | N2: gene3 | P2: cols regulators/rows targets | Q2: gene1 | R2: gene2 | S2: gene3 | U2: cols regulators/rows targets | V2: gene1 | W2: gene2 | X2: gene3
A3: gene1 | B3: -1 | C3: 0 | D3: 0 | F3: gene1 | G3: -0.99988383 | H3: 0 | I3: 0 | K3: gene1 | L3: -0.83804442 | M3: 0 | N3: 0 | P3: gene1 | Q3: -0.99997936 | R3: 0 | S3: 0 | U3: gene1 | V3: -0.99999993 | W3: 0 | X3: 0
A4: gene2 | B4: 0 | C4: 1 | D4: 0 | F4: gene2 | G4: 0 | H4: 1.0006503 | I4: 0 | K4: gene2 | L4: 0 | M4: 0.99508487 | N4: 0 | P4: gene2 | Q4: 0 | R4: 0.99999269 | S4: 0 | U4: gene2 | V4: 0 | W4: 1.0000003 | X4: 0
A5: gene3 | B5: -2 | C5: 2 | D5: 0 | F5: gene3 | G5: -1.9823247 | H5: 1.9850323 | I5: 0 | K5: gene3 | L5: -1.3862688 | M5: 0.37826617 | N5: 0 | P5: gene3 | Q5: -1.9999309 | R5: 1.9999604 | S5: 0 | U5: gene3 | V5: -1.9998528 | W5: 1.9999318 | X5: 0
F7: difference squared:
G8: =(G3-B3)^2 -> 1.349606e-08 | H8: =(H3-C3)^2 -> 0 | I8: =(I3-D3)^2 -> 0 | L8: =(L3-B3)^2 -> 0.02622961 | M8: =(M3-C3)^2 -> 0 | N8: =(N3-D3)^2 -> 0 | Q8: =(Q3-B3)^2 -> 4.26178e-10 | R8: =(R3-C3)^2 -> 0 | S8: =(S3-D3)^2 -> 0 | V8: =(V3-B3)^2 -> 5.607205e-15 | W8: =(W3-C3)^2 -> 0 | X8: =(X3-D3)^2 -> 0
G9: =(G4-B4)^2 -> 0 | H9: =(H4-C4)^2 -> 4.2288332e-07 | I9: =(I4-D4)^2 -> 0 | L9: =(L4-B4)^2 -> 0 | M9: =(M4-C4)^2 -> 2.4158504e-05 | N9: =(N4-D4)^2 -> 0 | Q9: =(Q4-B4)^2 -> 0 | R9: =(R4-C4)^2 -> 5.3373987e-11 | S9: =(S4-D4)^2 -> 0 | V9: =(V4-B4)^2 -> 0 | W9: =(W4-C4)^2 -> 8.2679446e-14 | X9: =(X4-D4)^2 -> 0
G10: =(G5-B5)^2 -> 0.00031241487 | H10: =(H5-C5)^2 -> 0.00022403229 | I10: =(I5-D5)^2 -> 0 | L10: =(L5-B5)^2 -> 0.37666597 | M10: =(M5-C5)^2 -> 2.6300206 | N10: =(N5-D5)^2 -> 0 | Q10: =(Q5-B5)^2 -> 4.7706637e-09 | R10: =(R5-C5)^2 -> 1.5659808e-09 | S10: =(S5-D5)^2 -> 0 | V10: =(V5-B5)^2 -> 2.1667889e-08 | W10: =(W5-C5)^2 -> 4.6518065e-09 | X10: =(X5-D5)^2 -> 0
F12: sum:
G13: =SUM(G8:I10) -> 0.00053688354 | L13: =SUM(L8:N10) -> 3.0329404 | Q13: =SUM(Q8:S10) -> 6.8161965e-09 | V13: =SUM(V8:X10) -> 2.6319783e-08
A19: Making sure the expression data is good
A20: 15 | B20: 30 | C20: 60
A21: -0.54237338 | B21: -0.56652723 | C21: -0.56746432
A22: 0.63370583 | B22: 0.73320987 | C22: 0.75435865
A23: 0.61901321 | B23: 0.7858158 | C23: 0.82005694
A26: id | B26: 15 | C26: 15 | D26: 15 | E26: 15 | F26: 30 | G26: 30 | H26: 30 | I26: 30 | J26: 30 | K26: 60 | L26: 60 | M26: 60 | N26: 60
A27: gene1 | B27: -0.54237338 | C27: -0.54237338 | D27: -0.54237338 | E27: -0.54237338 | F27: -0.56652723 | G27: -0.56652723 | H27: -0.56652723 | I27: -0.56652723 | J27: -0.56652723 | K27: -0.56746432 | L27: -0.56746432 | M27: -0.56746432 | N27: -0.56746432
A28: gene2 | B28: 0.63370583 | C28: 0.63370583 | D28: 0.63370583 | E28: 0.63370583 | F28: 0.73320987 | G28: 0.73320987 | H28: 0.73320987 | I28: 0.73320987 | J28: 0.73320987 | K28: 0.75435865 | L28: 0.75435865 | M28: 0.75435865 | N28: 0.75435865
A29: gene3 | B29: 0.61901321 | C29: 0.61901321 | D29: 0.61901321 | E29: 0.61901321 | F29: 0.7858158 | G29: 0.7858158 | H29: 0.7858158 | I29: 0.7858158 | J29: 0.7858158 | K29: 0.82005694 | L29: 0.82005694 | M29: 0.82005694 | N29: 0.82005694
B31: =(B27-A21) -> -2.220446e-16 | C31: =(C27-A21) -> -2.220446e-16 | D31: =(D27-A21) -> -2.220446e-16 | E31: =(E27-A21) -> -2.220446e-16 | F31: =F27-B21 -> 0 | G31: =G27-B21 -> 0 | H31: =H27-B21 -> 0 | I31: =I27-B21 -> 0 | J31: =J27-B21 -> 0 | K31: =K27-C21 -> 0 | L31: =L27-C21 -> 0 | M31: =M27-C21 -> 0 | N31: =N27-C21 -> 0
B32: =(B28-A22) -> -1.110223e-16 | C32: =(C28-A22) -> -1.110223e-16 | D32: =(D28-A22) -> -1.110223e-16 | E32: =(E28-A22) -> -1.110223e-16 | F32: =F28-B22 -> 0 | G32: =G28-B22 -> 0 | H32: =H28-B22 -> 0 | I32: =I28-B22 -> 0 | J32: =J28-B22 -> 0 | K32: =K28-C22 -> 0 | L32: =L28-C22 -> 0 | M32: =M28-C22 -> 0 | N32: =N28-C22 -> 0
B33: =(B29-A23) -> -2.220446e-16 | C33: =(C29-A23) -> -2.220446e-16 | D33: =(D29-A23) -> -2.220446e-16 | E33: =(E29-A23) -> -2.220446e-16 | F33: =F29-B23 -> 0 | G33: =G29-B23 -> 0 | H33: =H29-B23 -> 0 | I33: =I29-B23 -> 0 | J33: =J29-B23 -> 0 | K33: =K29-C23 -> 0 | L33: =L29-C23 -> 0 | M33: =M29-C23 -> 0 | N33: =N29-C23 -> 0

Sheet 19.08
A1: Input weights: | F1: B constant: | K1: No constant: | P1: P constant: | U1: PB constant:
A2: cols regulators/rows targets | B2: gene1 | C2: gene2 | D2: gene3 | F2: cols regulators/rows targets | G2: gene1 | H2: gene2 | I2: gene3 | K2: cols regulators/rows targets | L2: gene1 | M2: gene2 | N2: gene3 | P2: cols regulators/rows targets | Q2: gene1 | R2: gene2 | S2: gene3 | U2: cols regulators/rows targets | V2: gene1 | W2: gene2 | X2: gene3
A3: gene1 | B3: -1 | C3: 0 | D3: 0 | F3: gene1 | G3: -5.2554496 | H3: 0 | I3: 0 | K3: gene1 | L3: -0.74877605 | M3: 0 | N3: 0 | P3: gene1 | Q3: -0.99998979 | R3: 0 | S3: 0 | U3: gene1 | V3: -0.99999989 | W3: 0 | X3: 0
A4: gene2 | B4: 0 | C4: 2 | D4: 0 | F4: gene2 | G4: 0 | H4: 0.14463664 | I4: 0 | K4: gene2 | L4: 0 | M4: 0.1173457 | N4: 0 | P4: gene2 | Q4: 0 | R4: 1.9999895 | S4: 0 | U4: gene2 | V4: 0 | W4: 1.9999904 | X4: 0
A5: gene3 | B5: -2 | C5: 1 | D5: 0 | F5: gene3 | G5: -5.763085 | H5: 0.40617692 | I5: 0 | K5: gene3 | L5: -1.8781143 | M5: 0.41561244 | N5: 0 | P5: gene3 | Q5: -1.9999733 | R5: 0.9999909 | S5: 0 | U5: gene3 | V5: -1.9999778 | W5: 0.99999216 | X5: 0
F7: difference squared:
G8: =(G3-B3)^2 -> 18.108851 | H8: =(H3-C3)^2 -> 0 | I8: =(I3-D3)^2 -> 0 | L8: =(L3-B3)^2 -> 0.063113475 | M8: =(M3-C3)^2 -> 0 | N8: =(N3-D3)^2 -> 0 | Q8: =(Q3-B3)^2 -> 1.0421296e-10 | R8: =(R3-C3)^2 -> 0 | S8: =(S3-D3)^2 -> 0 | V8: =(V3-B3)^2 -> 1.2117954e-14 | W8: =(W3-C3)^2 -> 0 | X8: =(X3-D3)^2 -> 0
G9: =(G4-B4)^2 -> 0 | H9: =(H4-C4)^2 -> 3.4423732 | I9: =(I4-D4)^2 -> 0 | L9: =(L4-B4)^2 -> 0 | M9: =(M4-C4)^2 -> 3.5443872 | N9: =(N4-D4)^2 -> 0 | Q9: =(Q4-B4)^2 -> 0 | R9: =(R4-C4)^2 -> 1.0994409e-10 | S9: =(S4-D4)^2 -> 0 | V9: =(V4-B4)^2 -> 0 | W9: =(W4-C4)^2 -> 9.2417338e-11 | X9: =(X4-D4)^2 -> 0
G10: =(G5-B5)^2 -> 14.160809 | H10: =(H5-C5)^2 -> 0.35262586 | I10: =(I5-D5)^2 -> 0 | L10: =(L5-B5)^2 -> 0.014856127 | M10: =(M5-C5)^2 -> 0.34150882 | N10: =(N5-D5)^2 -> 0 | Q10: =(Q5-B5)^2 -> 7.1450148e-10 | R10: =(R5-C5)^2 -> 8.2872621e-11 | S10: =(S5-D5)^2 -> 0 | V10: =(V5-B5)^2 -> 4.9231414e-10 | W10: =(W5-C5)^2 -> 6.1435874e-11 | X10: =(X5-D5)^2 -> 0
F12: sum:
G13: =SUM(G8:I10) -> 36.064659 | L13: =SUM(L8:N10) -> 3.9638656 | Q13: =SUM(Q8:S10) -> 1.0115312e-09 | V13: =SUM(V8:X10) -> 6.4617947e-10
A19: Making sure the expression data is good
A20: 15 | B20: 30 | C20: 60
A21: -0.54224305 | B21: -0.56654145 | C21: -0.56746433
A22: 0.87472277 | B22: 0.96025868 | C22: 0.97145734
A23: 0.13290994 | B23: 0.33335865 | C23: 0.37371699
A26: id | B26: 15 | C26: 15 | D26: 15 | E26: 15 | F26: 30 | G26: 30 | H26: 30 | I26: 30 | J26: 30 | K26: 60 | L26: 60 | M26: 60 | N26: 60
A27: gene1 | B27: -0.54224305 | C27: -0.54224305 | D27: -0.54224305 | E27: -0.54224305 | F27: -0.56654145 | G27: -0.56654145 | H27: -0.56654145 | I27: -0.56654145 | J27: -0.56654145 | K27: -0.56746433 | L27: -0.56746433 | M27: -0.56746433 | N27: -0.56746433
A28: gene2 | B28: 0.87472277 | C28: 0.87472277 | D28: 0.87472277 | E28: 0.87472277 | F28: 0.96025868 | G28: 0.96025868 | H28: 0.96025868 | I28: 0.96025868 | J28: 0.96025868 | K28: 0.97145734 | L28: 0.97145734 | M28: 0.97145734 | N28: 0.97145734
A29: gene3 | B29: 0.13290994 | C29: 0.13290994 | D29: 0.13290994 | E29: 0.13290994 | F29: 0.33335865 | G29: 0.33335865 | H29: 0.33335865 | I29: 0.33335865 | J29: 0.33335865 | K29: 0.37371699 | L29: 0.37371699 | M29: 0.37371699 | N29: 0.37371699
B31: =(B27-A21) -> -1.110223e-16 | C31: =(C27-A21) -> -1.110223e-16 | D31: =(D27-A21) -> -1.110223e-16 | E31: =(E27-A21) -> -1.110223e-16 | F31: =F27-B21 -> 0 | G31: =G27-B21 -> 0 | H31: =H27-B21 -> 0 | I31: =I27-B21 -> 0 | J31: =J27-B21 -> 0 | K31: =K27-C21 -> 0 | L31: =L27-C21 -> 0 | M31: =M27-C21 -> 0 | N31: =N27-C21 -> 0
B32: =(B28-A22) -> 1.110223e-16 | C32: =(C28-A22) -> 1.110223e-16 | D32: =(D28-A22) -> 1.110223e-16 | E32: =(E28-A22) -> 1.110223e-16 | F32: =F28-B22 -> 0 | G32: =G28-B22 -> 0 | H32: =H28-B22 -> 0 | I32: =I28-B22 -> 0 | J32: =J28-B22 -> 0 | K32: =K28-C22 -> 0 | L32: =L28-C22 -> 0 | M32: =M28-C22 -> 0 | N32: =N28-C22 -> 0
B33: =(B29-A23) -> 1.3877788e-16 | C33: =(C29-A23) -> 1.3877788e-16 | D33: =(D29-A23) -> 1.3877788e-16 | E33: =(E29-A23) -> 1.3877788e-16 | F33: =F29-B23 -> 4.9960036e-16 | G33: =G29-B23 -> 4.9960036e-16 | H33: =H29-B23 -> 4.9960036e-16 | I33: =I29-B23 -> 4.9960036e-16 | J33: =J29-B23 -> 4.9960036e-16 | K33: =K29-C23 -> 4.4408921e-16 | L33: =L29-C23 -> 4.4408921e-16 | M33: =M29-C23 -> 4.4408921e-16 | N33: =N29-C23 -> 4.4408921e-16

Sheet 19.09
A1: Input weights: | F1: B constant: | K1: No constant: | P1: P constant: | U1: PB constant:
A2: cols regulators/rows targets | B2: gene1 | C2: gene2 | D2: gene3 | F2: cols regulators/rows targets | G2: gene1 | H2: gene2 | I2: gene3 | K2: cols regulators/rows targets | L2: gene1 | M2: gene2 | N2: gene3 | P2: cols regulators/rows targets | Q2: gene1 | R2: gene2 | S2: gene3 | U2: cols regulators/rows targets | V2: gene1 | W2: gene2 | X2: gene3
A3: gene1 | B3: -1 | C3: 0 | D3: 0 | F3: gene1 | G3: -0.99994047 | H3: 0 | I3: 0 | K3: gene1 | L3: -0.76568114 | M3: 0 | N3: 0 | P3: gene1 | Q3: -0.99984043 | R3: 0 | S3: 0 | U3: gene1 | V3: -0.99999988 | W3: 0 | X3: 0
A4: gene2 | B4: 0 | C4: -2 | D4: 0 | F4: gene2 | G4: 0 | H4: -1.9999881 | I4: 0 | K4: gene2 | L4: 0 | M4: -1.8292291 | N4: 0 | P4: gene2 | Q4: 0 | R4: -1.9996161 | S4: 0 | U4: gene2 | V4: 0 | W4: -1.9999996 | X4: 0
A5: gene3 | B5: 1 | C5: 2 | D5: 0 | F5: gene3 | G5: 0.99987924 | H5: 1.9998737 | I5: 0 | K5: gene3 | L5: 0.70353826 | M5: 0.7661291 | N5: 0 | P5: gene3 | Q5: 0.99992593 | R5: 1.9996339 | S5: 0 | U5: gene3 | V5: 0.99999908 | W5: 1.999999 | X5: 0
F7: difference squared:
G8: =(G3-B3)^2 -> 3.5432666e-09 | H8: =(H3-C3)^2 -> 0 | I8: =(I3-D3)^2 -> 0 | L8: =(L3-B3)^2 -> 0.054905328 | M8: =(M3-C3)^2 -> 0 | N8: =(N3-D3)^2 -> 0 | Q8: =(Q3-B3)^2 -> 2.5462643e-08 | R8: =(R3-C3)^2 -> 0 | S8: =(S3-D3)^2 -> 0 | V8: =(V3-B3)^2 -> 1.5597361e-14 | W8: =(W3-C3)^2 -> 0 | X8: =(X3-D3)^2 -> 0
G9: =(G4-B4)^2 -> 0 | H9: =(H4-C4)^2 -> 1.4119006e-10 | I9: =(I4-D4)^2 -> 0 | L9: =(L4-B4)^2 -> 0 | M9: =(M4-C4)^2 -> 0.029162711 | N9: =(N4-D4)^2 -> 0 | Q9: =(Q4-B4)^2 -> 0 | R9: =(R4-C4)^2 -> 1.4738391e-07 | S9: =(S4-D4)^2 -> 0 | V9: =(V4-B4)^2 -> 0 | W9: =(W4-C4)^2 -> 1.9283316e-13 | X9: =(X4-D4)^2 -> 0
G10: =(G5-B5)^2 -> 1.4583792e-08 | H10: =(H5-C5)^2 -> 1.5951483e-08 | I10: =(I5-D5)^2 -> 0 | L10: =(L5-B5)^2 -> 0.087889561 | M10: =(M5-C5)^2 -> 1.5224374 | N10: =(N5-D5)^2 -> 0 | Q10: =(Q5-B5)^2 -> 5.4869855e-09 | R10: =(R5-C5)^2 -> 1.3399672e-07 | S10: =(S5-D5)^2 -> 0 | V10: =(V5-B5)^2 -> 8.4734981e-13 | W10: =(W5-C5)^2 -> 1.0323638e-12 | X10: =(X5-D5)^2 -> 0
F12: sum:
G13: =SUM(G8:I10) -> 3.4219731e-08 | L13: =SUM(L8:N10) -> 1.694395 | Q13: =SUM(Q8:S10) -> 3.1233025e-07 | V13: =SUM(V8:X10) -> 2.0881441e-12
A19: Making sure the expression data is good
A20: 15 | B20: 30 | C20: 60
A21: -0.54229869 | B21: -0.56653258 | C21: -0.56746433
A22: -0.91503905 | B22: -0.93939714 | C22: -0.9398715
A23: 0.73163825 | B23: 0.75948181 | C23: 0.76166262
A26: id | B26: 15 | C26: 15 | D26: 15 | E26: 15 | F26: 30 | G26: 30 | H26: 30 | I26: 30 | J26: 30 | K26: 60 | L26: 60 | M26: 60 | N26: 60
A27: gene1 | B27: -0.54229869 | C27: -0.54229869 | D27: -0.54229869 | E27: -0.54229869 | F27: -0.56653258 | G27: -0.56653258 | H27: -0.56653258 | I27: -0.56653258 | J27: -0.56653258 | K27: -0.56746433 | L27: -0.56746433 | M27: -0.56746433 | N27: -0.56746433
A28: gene2 | B28: -0.91503905 | C28: -0.91503905 | D28: -0.91503905 | E28: -0.91503905 | F28: -0.93939714 | G28: -0.93939714 | H28: -0.93939714 | I28: -0.93939714 | J28: -0.93939714 | K28: -0.9398715 | L28: -0.9398715 | M28: -0.9398715 | N28: -0.9398715
A29: gene3 | B29: 0.73163825 | C29: 0.73163825 | D29: 0.73163825 | E29: 0.73163825 | F29: 0.75948181 | G29: 0.75948181 | H29: 0.75948181 | I29: 0.75948181 | J29: 0.75948181 | K29: 0.76166262 | L29: 0.76166262 | M29: 0.76166262 | N29: 0.76166262
B31: =(B27-A21) -> 4.4408921e-16 | C31: =(C27-A21) -> 4.4408921e-16 | D31: =(D27-A21) -> 4.4408921e-16 | E31: =(E27-A21) -> 4.4408921e-16 | F31: =F27-B21 -> 0 | G31: =G27-B21 -> 0 | H31: =H27-B21 -> 0 | I31: =I27-B21 -> 0 | J31: =J27-B21 -> 0 | K31: =K27-C21 -> 0 | L31: =L27-C21 -> 0 | M31: =M27-C21 -> 0 | N31: =N27-C21 -> 0
B32: =(B28-A22) -> -1.110223e-16 | C32: =(C28-A22) -> -1.110223e-16 | D32: =(D28-A22) -> -1.110223e-16 | E32: =(E28-A22) -> -1.110223e-16 | F32: =F28-B22 -> 0 | G32: =G28-B22 -> 0 | H32: =H28-B22 -> 0 | I32: =I28-B22 -> 0 | J32: =J28-B22 -> 0 | K32: =K28-C22 -> 0 | L32: =L28-C22 -> 0 | M32: =M28-C22 -> 0 | N32: =N28-C22 -> 0
B33: =(B29-A23) -> 1.110223e-16 | C33: =(C29-A23) -> 1.110223e-16 | D33: =(D29-A23) -> 1.110223e-16 | E33: =(E29-A23) -> 1.110223e-16 | F33: =F29-B23 -> 0 | G33: =G29-B23 -> 0 | H33: =H29-B23 -> 0 | I33: =I29-B23 -> 0 | J33: =J29-B23 -> 0 | K33: =K29-C23 -> 0 | L33: =L29-C23 -> 0 | M33: =M29-C23 -> 0 | N33: =N29-C23 -> 0

Sheet 19.10
A1: Input weights: | F1: B constant: | K1: No constant: | P1: P constant: | U1: PB constant:
A2: cols regulators/rows targets | B2: gene1 | C2: gene2 | D2: gene3 | F2: cols regulators/rows targets | G2: gene1 | H2: gene2 | I2: gene3 | K2: cols regulators/rows targets | L2: gene1 | M2: gene2 | N2: gene3 | P2: cols regulators/rows targets | Q2: gene1 | R2: gene2 | S2: gene3 | U2: cols regulators/rows targets | V2: gene1 | W2: gene2 | X2: gene3
A3: gene1 | B3: -1 | C3: 0 | D3: 0 | F3: gene1 | G3: -5.7595876 | H3: 0 | I3: 0 | K3: gene1 | L3: -0.74574033 | M3: 0 | N3: 0 | P3: gene1 | Q3: -0.99999361 | R3: 0 | S3: 0 | U3: gene1 | V3: -0.99999995 | W3: 0 | X3: 0
A4: gene2 | B4: 0 | C4: 2 | D4: 0 | F4: gene2 | G4: 0 | H4: 2.0276642 | I4: 0 | K4: gene2 | L4: 0 | M4: 2.087277 | N4: 0 | P4: gene2 | Q4: 0 | R4: 1.9999912 | S4: 0 | U4: gene2 | V4: 0 | W4: 1.9999911 | X4: 0
A5: gene3 | B5: 1 | C5: -2 | D5: 0 | F5: gene3 | G5: 1.8193299 | H5: -2.1331873 | I5: 0 | K5: gene3 | L5: 0.52774208 | M5: -1.963114 | N5: 0 | P5: gene3 | Q5: 0.99999341 | R5: -1.9999976 | S5: 0 | U5: gene3 | V5: 0.99998926 | W5: -1.9999969 | X5: 0
F7: difference squared:
G8: =(G3-B3)^2 -> 22.653674 | H8: =(H3-C3)^2 -> 0 | I8: =(I3-D3)^2 -> 0 | L8: =(L3-B3)^2 -> 0.064647982 | M8: =(M3-C3)^2 -> 0 | N8: =(N3-D3)^2 -> 0 | Q8: =(Q3-B3)^2 -> 4.0877773e-11 | R8: =(R3-C3)^2 -> 0 | S8: =(S3-D3)^2 -> 0 | V8: =(V3-B3)^2 -> 2.636763e-15 | W8: =(W3-C3)^2 -> 0 | X8: =(X3-D3)^2 -> 0
G9: =(G4-B4)^2 -> 0 | H9: =(H4-C4)^2 -> 0.00076530535 | I9: =(I4-D4)^2 -> 0 | L9: =(L4-B4)^2 -> 0 | M9: =(M4-C4)^2 -> 0.0076172801 | N9: =(N4-D4)^2 -> 0 | Q9: =(Q4-B4)^2 -> 0 | R9: =(R4-C4)^2 -> 7.8158722e-11 | S9: =(S4-D4)^2 -> 0 | V9: =(V4-B4)^2 -> 0 | W9: =(W4-C4)^2 -> 7.9838765e-11 | X9: =(X4-D4)^2 -> 0
G10: =(G5-B5)^2 -> 0.67130151 | H10: =(H5-C5)^2 -> 0.017738847 | I10: =(I5-D5)^2 -> 0 | L10: =(L5-B5)^2 -> 0.22302754 | M10: =(M5-C5)^2 -> 0.0013605792 | N10: =(N5-D5)^2 -> 0 | Q10: =(Q5-B5)^2 -> 4.339375e-11 | R10: =(R5-C5)^2 -> 5.7263473e-12 | S10: =(S5-D5)^2 -> 0 | V10: =(V5-B5)^2 -> 1.1539182e-10 | W10: =(W5-C5)^2 -> 9.5369959e-12 | X10: =(X5-D5)^2 -> 0
F12: sum:
G13: =SUM(G8:I10) -> 23.34348 | L13: =SUM(L8:N10) -> 0.29665338 | Q13: =SUM(Q8:S10) -> 1.6815659e-10 | V13: =SUM(V8:X10) -> 2.0477022e-10
A19: Making sure the expression data is good
A20: 15 | B20: 30 | C20: 60
A21: -0.54228874 | B21: -0.56653031 | C21: -0.56746432
A22: 0.87474027 | B22: 0.96025454 | C22: 0.97145731
A23: -2.0997422 | B23: -3.3840198 | C23: -3.7334986
A26: id | B26: 15 | C26: 15 | D26: 15 | E26: 15 | F26: 30 | G26: 30 | H26: 30 | I26: 30 | J26: 30 | K26: 60 | L26: 60 | M26: 60 | N26: 60
A27: gene1 | B27: -0.54228874 | C27: -0.54228874 | D27: -0.54228874 | E27: -0.54228874 | F27: -0.56653031 | G27: -0.56653031 | H27: -0.56653031 | I27: -0.56653031 | J27: -0.56653031 | K27: -0.56746432 | L27: -0.56746432 | M27: -0.56746432 | N27: -0.56746432
A28: gene2 | B28: 0.87474027 | C28: 0.87474027 | D28: 0.87474027 | E28: 0.87474027 | F28: 0.96025454 | G28: 0.96025454 | H28: 0.96025454 | I28: 0.96025454 | J28: 0.96025454 | K28: 0.97145731 | L28: 0.97145731 | M28: 0.97145731 | N28: 0.97145731
A29: gene3 | B29: -2.0997422 | C29: -2.0997422 | D29: -2.0997422 | E29: -2.0997422 | F29: -3.3840198 | G29: -3.3840198 | H29: -3.3840198 | I29: -3.3840198 | J29: -3.3840198 | K29: -3.7334986 | L29: -3.7334986 | M29: -3.7334986 | N29: -3.7334986
B31: =(B27-A21) -> -1.110223e-16 | C31: =(C27-A21) -> -1.110223e-16 | D31: =(D27-A21) -> -1.110223e-16 | E31: =(E27-A21) -> -1.110223e-16 | F31: =F27-B21 -> 0 | G31: =G27-B21 -> 0 | H31: =H27-B21 -> 0 | I31: =I27-B21 -> 0 | J31: =J27-B21 -> 0 | K31: =K27-C21 -> 0 | L31: =L27-C21 -> 0 | M31: =M27-C21 -> 0 | N31: =N27-C21 -> 0
B32: =(B28-A22) -> 0 | C32: =(C28-A22) -> 0 | D32: =(D28-A22) -> 0 | E32: =(E28-A22) -> 0 | F32: =F28-B22 -> 0 | G32: =G28-B22 -> 0 | H32: =H28-B22 -> 0 | I32: =I28-B22 -> 0 | J32: =J28-B22 -> 0 | K32: =K28-C22 -> 0 | L32: =L28-C22 -> 0 | M32: =M28-C22 -> 0 | N32: =N28-C22 -> 0
B33: =(B29-A23) -> 3.5527137e-15 | C33: =(C29-A23) -> 3.5527137e-15 | D33: =(D29-A23) -> 3.5527137e-15 | E33: =(E29-A23) -> 3.5527137e-15 | F33: =F29-B23 -> 0 | G33: =G29-B23 -> 0 | H33: =H29-B23 -> 0 | I33: =I29-B23 -> 0 | J33: =J29-B23 -> 0 | K33: =K29-C23 -> 0 | L33: =L29-C23 -> 0 | M33: =M29-C23 -> 0 | N33: =N29-C23 -> 0

Sheet 19.11
A1: Input weights: | F1: B constant: | K1: No constant: | P1: P constant: | U1: PB constant:
A2: cols regulators/rows targets | B2: gene1 | C2: gene2 | D2: gene3 | F2: cols regulators/rows targets | G2: gene1 | H2: gene2 | I2: gene3 | K2: cols regulators/rows targets | L2: gene1 | M2: gene2 | N2: gene3 | P2: cols regulators/rows targets | Q2: gene1 | R2: gene2 | S2: gene3 | U2: cols regulators/rows targets | V2: gene1 | W2: gene2 | X2: gene3
A3: gene1 | B3: -1 | C3: 0 | D3: 0 | F3: gene1 | G3: -0.99993541 | H3: 0 | I3: 0 | K3: gene1 | L3: -0.86140621 | M3: 0 | N3: 0 | P3: gene1 | Q3: -0.99985761 | R3: 0 | S3: 0 | U3: gene1 | V3: -0.99999986 | W3: 0 | X3: 0
A4: gene2 | B4: 0 | C4: -2 | D4: 0 | F4: gene2 | G4: 0 | H4: -1.9999999 | I4: 0 | K4: gene2 | L4: 0 | M4: -1.7762404 | N4: 0 | P4: gene2 | Q4: 0 | R4: -1.9996582 | S4: 0 | U4: gene2 | V4: 0 | W4: -1.9999996 | X4: 0
A5: gene3 | B5: 2 | C5: 1 | D5: 0 | F5: gene3 | G5: 1.9998457 | H5: 0.99990544 | I5: 0 | K5: gene3 | L5: 0.62444189 | M5: 0.12772309 | N5: 0 | P5: gene3 | Q5: 1.99972 | R5: 0.99991126 | S5: 0 | U5: gene3 | V5: 1.9999987 | W5: 0.99999916 | X5: 0
F7: difference squared:
G8: =(G3-B3)^2 -> 4.1715407e-09 | H8: =(H3-C3)^2 -> 0 | I8: =(I3-D3)^2 -> 0 | L8: =(L3-B3)^2 -> 0.019208237 | M8: =(M3-C3)^2 -> 0 | N8: =(N3-D3)^2 -> 0 | Q8: =(Q3-B3)^2 -> 2.0274724e-08 | R8: =(R3-C3)^2 -> 0 | S8: =(S3-D3)^2 -> 0 | V8: =(V3-B3)^2 -> 1.9966586e-14 | W8: =(W3-C3)^2 -> 0 | X8: =(X3-D3)^2 -> 0
G9: =(G4-B4)^2 -> 0 | H9: =(H4-C4)^2 -> 8.1132847e-15 | I9: =(I4-D4)^2 -> 0 | L9: =(L4-B4)^2 -> 0 | M9: =(M4-C4)^2 -> 0.050068364 | N9: =(N4-D4)^2 -> 0 | Q9: =(Q4-B4)^2 -> 0 | R9: =(R4-C4)^2 -> 1.1681455e-07 | S9: =(S4-D4)^2 -> 0 | V9: =(V4-B4)^2 -> 0 | W9: =(W4-C4)^2 -> 1.4848746e-13 | X9: =(X4-D4)^2 -> 0
G10: =(G5-B5)^2 -> 2.3810339e-08 | H10: =(H5-C5)^2 -> 8.9411277e-09 | I10: =(I5-D5)^2 -> 0 | L10: =(L5-B5)^2 -> 1.8921601 | M10: =(M5-C5)^2 -> 0.76086701 | N10: =(N5-D5)^2 -> 0 | Q10: =(Q5-B5)^2 -> 7.8388713e-08 | R10: =(R5-C5)^2 -> 7.8742438e-09 | S10: =(S5-D5)^2 -> 0 | V10: =(V5-B5)^2 -> 1.6833175e-12 | W10: =(W5-C5)^2 -> 7.0220467e-13 | X10: =(X5-D5)^2 -> 0
F12: sum:
G13: =SUM(G8:I10) -> 3.6923016e-08 | L13: =SUM(L8:N10) -> 2.7223037 | Q13: =SUM(Q8:S10) -> 2.2335223e-07 | V13: =SUM(V8:X10) -> 2.5539762e-12
A19: Making sure the expression data is good
